Workbook

Sheet Data Dictionary
A1: GreenLeaf Foods Nigeria Ltd — HR Dataset
A2: Data Analysis with Microsoft Excel · Capstone Dataset · Cemr Scripts
A4: Column | B4: Description
A5: EmployeeID | B5: Unique staff identifier. NOTE: the raw sheet contains a few duplicate rows to be removed.
A6: First Name / Last Name | B6: Employee name. Some last names carry trailing spaces (clean with TRIM).
A7: Gender | B7: Should be Male/Female. Some rows use 'M'/'F' and must be standardised.
A8: Department | B8: One of 8 departments. Casing/spacing is inconsistent on some rows (clean with TRIM/PROPER).
A9: Job Role | B9: Role title; maps to a Grade in the 'Grade Bands' sheet.
A10: Location | B10: Office/branch city.
A11: Hire Date | B11: Date the employee joined.
A12: Exit Date | B12: Date the employee left. BLANK means the employee is still active.
A13: Monthly Salary (NGN) | B13: Gross monthly pay in Naira.
A14: Performance Rating | B14: Latest appraisal score, 1 (low) to 5 (high). A few are blank.
A15: Date of Birth | B15: Used to derive employee age.

Sheet Employee Data
A1: EmployeeID | B1: First Name | C1: Last Name | D1: Gender | E1: Department | F1: Job Role | G1: Location | H1: Hire Date | I1: Exit Date | J1: Monthly Salary (NGN) | K1: Performance Rating | L1: Date of Birth
A2: 1001 | B2: Uche | C2: Suleiman | D2: M | E2: it | F2: IT Support | G2: Lagos | H2: 42938 | J2: 180000 | K2: 4 | L2: 31611
A3: 1002 | B3: Ronke | C3: Okafor | D3: Female | E3: Operations | F3: Operations Officer | G3: Ibadan | H3: 42475 | J3: 166000 | K3: 4 | L3: 32195
A4: 1003 | B4: Sadiq | C4: Olawale | D4: Male | E4: Operations | F4: Operations Analyst | G4: Kano | H4: 44193 | J4: 180000 | K4: 3 | L4: 35812
A5: 1004 | B5: Bode | C5: Oladele | D5: Male | E5: Human Resources | F5: Recruiter | G5: Lagos | H5: 42547 | J5: 197000 | K5: 3 | L5: 34845
A6: 1005 | B6: Damilola | C6: Okoro | D6: M | E6: Customer Service | F6: Support Agent | G6: Lagos | H6: 43836 | I6: 45658 | J6: 113000 | K6: 3 | L6: 34826
A7: 1006 | B7: Precious | C7: Oladele | D7: F | E7: Operations | F7: Operations Officer | G7: Lagos | H7: 43824 | J7: 130000 | K7: 4 | L7: 36398
A8: 1007 | B8: Segun | C8: Okoro | D8: Male | E8: Marketing | F8: Content Strategist | G8: Lagos | H8: 44428 | J8: 212000 | K8: 3 | L8: 27615
A9: 1008 | B9: Tunde | C9: Aliyu | D9: Male | E9: Customer Service | F9: Support Agent | G9: Ibadan | H9: 45109 | J9: 164000 | K9: 3 | L9: 33528
A10: 1009 | B10: Damilola | C10: Nwachukwu | D10: M | E10: Customer Service | F10: Team Lead | G10: Port Harcourt | H10: 44406 | I10: 45275 | J10: 317000 | L10: 30973
A11: 1010 | B11: Tunde | C11: Obi | D11: M | E11: Marketing | F11: Content Strategist | G11: Kano | H11: 42925 | J11: 167000 | K11: 4 | L11: 27973
A12: 1011 | B12: Efe | C12: Oladele | D12: M | E12: Finance | F12: Accounts Officer | G12: Port Harcourt | H12: 44345 | I12: 45416 | J12: 196000 | K12: 1 | L12: 33623
A13: 1012 | B13: Ronke | C13: Adeleke | D13: F | E13: Logistics | F13: Dispatch Officer | G13: Lagos | H13: 45576 | I13: 46000 | J13: 140000 | K13: 1 | L13: 31373
A14: 1013 | B14: Ibrahim | C14: Suleiman | D14: Male | E14: Human Resources | F14: HR Manager | G14: Lagos | H14: 45122 | J14: 545000 | K14: 4 | L14: 30917
A15: 1014 | B15: Maryam | C15: Okoro | D15: Female | E15: Customer Service | F15: Support Agent | G15: Kano | H15: 44823 | J15: 196000 | K15: 3 | L15: 27876
A16: 1015 | B16: Fatima | C16: Oladele | D16: Female | E16: MARKETING | F16: Content Strategist | G16: Lagos | H16: 43241 | J16: 224000 | K16: 4 | L16: 33362
A17: 1016 | B17: Amaka | C17: Bello | D17: Female | E17: Logistics | F17: Dispatch Officer | G17: Port Harcourt | H17: 45382 | J17: 149000 | K17: 4 | L17: 29946
A18: 1017 | B18: Folake | C18: Okoro | D18: Female | E18: IT | F18: Software Developer | G18: Lagos | H18: 42797 | J18: 161000 | K18: 3 | L18: 32449
A19: 1018 | B19: Damola | C19: Okafor | D19: F | E19: Marketing | F19: Content Strategist | G19: Ibadan | H19: 44904 | J19: 204000 | K19: 5 | L19: 33997
A20: 1019 | B20: Ella | C20: Aliyu | D20: F | E20: Finance | F20: Accountant | G20: Kano | H20: 43358 | J20: 174000 | K20: 3 | L20: 32862
A21: 1020 | B21: Damilola | C21: Aliyu | D21: Male | E21: Logistics | F21: Fleet Coordinator | G21: Port Harcourt | H21: 43637 | J21: 205000 | L21: 29886
A22: 1021 | B22: Kunle | C22: Nwosu | D22: Male | E22: Sales | F22: Sales Executive | G22: Ibadan | H22: 45356 | J22: 216000 | K22: 4 | L22: 35840
A23: 1022 | B23: Nonso | C23: Mohammed | D23: Male | E23: Operations | F23: Operations Analyst | G23: Lagos | H23: 44525 | I23: 45698 | J23: 228000 | K23: 4 | L23: 32315
A24: 1023 | B24: Musa | C24: Adeyemi | D24: Male | E24: Customer Service | F24: Support Agent | G24: Kano | H24: 44398 | J24: 174000 | K24: 4 | L24: 36270
A25: 1024 | B25: Chibuike | C25: Mohammed | D25: Male | E25: Sales | F25: Sales Manager | G25: Kano | H25: 45503 | J25: 516000 | K25: 3 | L25: 32624
A26: 1025 | B26: Bukola | C26: Anyanwu | D26: Female | E26: IT | F26: Software Developer | G26: Port Harcourt | H26: 45084 | J26: 198000 | K26: 3 | L26: 28598
A27: 1026 | B27: Femi | C27: Abubakar | D27: Male | E27: Human Resources | F27: HR Officer | G27: Port Harcourt | H27: 44376 | J27: 124000 | K27: 4 | L27: 34190
A28: 1027 | B28: Bukola | C28: Nwosu | D28: Female | E28: Sales | F28: Sales Executive | G28: Ibadan | H28: 42568 | I28: 44751 | J28: 152000 | K28: 3 | L28: 31346
A29: 1028 | B29: Ifeoma | C29: Olawale | D29: F | E29: IT | F29: IT Support | G29: Lagos | H29: 44158 | I29: 44930 | J29: 179000 | K29: 2 | L29: 31634
A30: 1029 | B30: Blessing | C30: Adebayo | D30: Female | E30: Logistics | F30: Logistics Analyst | G30: Lagos | H30: 43715 | J30: 322000 | K30: 4 | L30: 36654
A31: 1030 | B31: Ella | C31: Nwosu | D31: Female | E31: IT | F31: Systems Analyst | G31: Lagos | H31: 45410 | J31: 283000 | K31: 3 | L31: 29699
A32: 1031 | B32: Gbenga | C32: Akinyemi | D32: Male | E32: Sales | F32: Sales Executive | G32: Lagos | H32: 44555 | I32: 46009 | J32: 133000 | K32: 3 | L32: 36703
A33: 1032 | B33: Emeka | C33: Adebayo | D33: Male | E33: Sales | F33: Sales Executive | G33: Ibadan | H33: 43885 | J33: 148000 | K33: 1 | L33: 31757
A34: 1033 | B34: Ella | C34: Adeleke | D34: Female | E34: Customer Service | F34: Team Lead | G34: Lagos | H34: 44485 | J34: 258000 | K34: 5 | L34: 31240
A35: 1034 | B35: Chidi | C35: Okafor | D35: Male | E35: IT | F35: IT Support | G35: Ibadan | H35: 44375 | J35: 150000 | K35: 2 | L35: 32617
A36: 1035 | B36: Chibuike | C36: Okafor | D36: M | E36: Human Resources | F36: HR Officer | G36: Lagos | H36: 42922 | J36: 141000 | K36: 3 | L36: 32100
A37: 1036 | B37: Taiwo | C37: Abubakar | D37: Male | E37: Sales | F37: Sales Executive | G37: Port Harcourt | H37: 42387 | I37: 45716 | J37: 125000 | K37: 5 | L37: 34488
A38: 1037 | B38: Blessing | C38: Suleiman | D38: Female | E38: Finance | F38: Finance Manager | G38: Abuja | H38: 43172 | J38: 482000 | K38: 3 | L38: 37156
A39: 1038 | B39: Hauwa | C39: Anyanwu | D39: Female | E39: IT | F39: Software Developer | G39: Port Harcourt | H39: 42682 | J39: 177000 | K39: 2 | L39: 32622
A40: 1039 | B40: Rotimi | C40: Olawale | D40: Male | E40: Logistics | F40: Dispatch Officer | G40: Abuja | H40: 43155 | J40: 155000 | K40: 5 | L40: 28820
...

Sheet Cleaned Data
A1: EmployeeID | B1: First Name | C1: Last Name | D1: Gender | E1: Department | F1: Job Role | G1: Location | H1: Monthly Salary (NGN) | I1: Employee's Grade | J1: Band Min | K1: Band Max | L1: Salary Band Status | M1: Performance Rating | N1: Date of Birth | O1: Full Name | P1: Employment Status | Q1: Age | R1: Tenure in Years | S1: Annual Salary | T1: Hire Date | U1: Exit Date
A2: 1001 | B2: Uche | C2: Suleiman | D2: Male | E2: IT | F2: IT Support | G2: Lagos | H2: 180000 | I2: =_xlfn.XLOOKUP(F2,'Grade Bands'!$A$2:$A$31,'Grade Bands'!$B$2:$B$31,"Not Found") -> Officer | J2: =_xlfn.XLOOKUP(F2,'Grade Bands'!$A$2:$A$31,'Grade Bands'!$C$2:$C$31,"Not Found") -> 110000 | K2: =_xlfn.XLOOKUP(F2,'Grade Bands'!$A$2:$A$31,'Grade Bands'!$D$2:$D$31,"Not Found") -> 230000 | L2: =IF(AND(H2>=J2,H2<=K2),"Within Band","Outside Band") -> Within Band | M2: 4 | N2: 31611 | O2: Uche Suleiman | P2: Active | Q2: 40 | R2: 9 | S2: 2160000 | T2: 42938
A3: 1002 | B3: Ronke | C3: Okafor | D3: Female | E3: Operations | F3: Operations Officer | G3: Ibadan | H3: 166000 | I3: =_xlfn.XLOOKUP(F3,'Grade Bands'!$A$2:$A$31,'Grade Bands'!$B$2:$B$31,"Not Found") -> Officer | J3: =_xlfn.XLOOKUP(F3,'Grade Bands'!$A$2:$A$31,'Grade Bands'!$C$2:$C$31,"Not Found") -> 110000 | K3: =_xlfn.XLOOKUP(F3,'Grade Bands'!$A$2:$A$31,'Grade Bands'!$D$2:$D$31,"Not Found") -> 230000 | L3: =IF(AND(H3>=J3,H3<=K3),"Within Band","Outside Band") -> Within Band | M3: 4 | N3: 32195 | O3: Ronke Okafor | P3: Active | Q3: 38 | R3: 10 | S3: 1992000 | T3: 42475
A4: 1003 | B4: Sadiq | C4: Olawale | D4: Male | E4: Operations | F4: Operations Analyst | G4: Kano | H4: 180000 | I4: =_xlfn.XLOOKUP(F4,'Grade Bands'!$A$2:$A$31,'Grade Bands'!$B$2:$B$31,"Not Found") -> Senior | J4: =_xlfn.XLOOKUP(F4,'Grade Bands'!$A$2:$A$31,'Grade Bands'!$C$2:$C$31,"Not Found") -> 220000 | K4: =_xlfn.XLOOKUP(F4,'Grade Bands'!$A$2:$A$31,'Grade Bands'!$D$2:$D$31,"Not Found") -> 360000 | L4: =IF(AND(H4>=J4,H4<=K4),"Within Band","Outside Band") -> Outside Band | M4: 3 | N4: 35812 | O4: Sadiq Olawale | P4: Active | Q4: 28 | R4: 5 | S4: 2160000 | T4: 44193
A5: 1004 | B5: Bode | C5: Oladele | D5: Male | E5: Human Resources | F5: Recruiter | G5: Lagos | H5: 197000 | I5: =_xlfn.XLOOKUP(F5,'Grade Bands'!$A$2:$A$31,'Grade Bands'!$B$2:$B$31,"Not Found") -> Officer | J5: =_xlfn.XLOOKUP(F5,'Grade Bands'!$A$2:$A$31,'Grade Bands'!$C$2:$C$31,"Not Found") -> 110000 | K5: =_xlfn.XLOOKUP(F5,'Grade Bands'!$A$2:$A$31,'Grade Bands'!$D$2:$D$31,"Not Found") -> 230000 | L5: =IF(AND(H5>=J5,H5<=K5),"Within Band","Outside Band") -> Within Band | M5: 3 | N5: 34845 | O5: Bode Oladele | P5: Active | Q5: 31 | R5: 10 | S5: 2364000 | T5: 42547
A6: 1005 | B6: Damilola | C6: Okoro | D6: Male | E6: Customer Service | F6: Support Agent | G6: Lagos | H6: 113000 | I6: =_xlfn.XLOOKUP(F6,'Grade Bands'!$A$2:$A$31,'Grade Bands'!$B$2:$B$31,"Not Found") -> Officer | J6: =_xlfn.XLOOKUP(F6,'Grade Bands'!$A$2:$A$31,'Grade Bands'!$C$2:$C$31,"Not Found") -> 110000 | K6: =_xlfn.XLOOKUP(F6,'Grade Bands'!$A$2:$A$31,'Grade Bands'!$D$2:$D$31,"Not Found") -> 230000 | L6: =IF(AND(H6>=J6,H6<=K6),"Within Band","Outside Band") -> Within Band | M6: 3 | N6: 34826 | O6: Damilola Okoro | P6: Exited | Q6: 31 | R6: 4 | S6: 1356000 | T6: 43836 | U6: 45658
A7: 1006 | B7: Precious | C7: Oladele | D7: Female | E7: Operations | F7: Operations Officer | G7: Lagos | H7: 130000 | I7: =_xlfn.XLOOKUP(F7,'Grade Bands'!$A$2:$A$31,'Grade Bands'!$B$2:$B$31,"Not Found") -> Officer | J7: =_xlfn.XLOOKUP(F7,'Grade Bands'!$A$2:$A$31,'Grade Bands'!$C$2:$C$31,"Not Found") -> 110000 | K7: =_xlfn.XLOOKUP(F7,'Grade Bands'!$A$2:$A$31,'Grade Bands'!$D$2:$D$31,"Not Found") -> 230000 | L7: =IF(AND(H7>=J7,H7<=K7),"Within Band","Outside Band") -> Within Band | M7: 4 | N7: 36398 | O7: Precious Oladele | P7: Active | Q7: 26 | R7: 6 | S7: 1560000 | T7: 43824
A8: 1007 | B8: Segun | C8: Okoro | D8: Male | E8: Marketing | F8: Content Strategist | G8: Lagos | H8: 212000 | I8: =_xlfn.XLOOKUP(F8,'Grade Bands'!$A$2:$A$31,'Grade Bands'!$B$2:$B$31,"Not Found") -> Senior | J8: =_xlfn.XLOOKUP(F8,'Grade Bands'!$A$2:$A$31,'Grade Bands'!$C$2:$C$31,"Not Found") -> 220000 | K8: =_xlfn.XLOOKUP(F8,'Grade Bands'!$A$2:$A$31,'Grade Bands'!$D$2:$D$31,"Not Found") -> 360000 | L8: =IF(AND(H8>=J8,H8<=K8),"Within Band","Outside Band") -> Outside Band | M8: 3 | N8: 27615 | O8: Segun Okoro | P8: Active | Q8: 50 | R8: 4 | S8: 2544000 | T8: 44428
A9: 1008 | B9: Tunde | C9: Aliyu | D9: Male | E9: Customer Service | F9: Support Agent | G9: Ibadan | H9: 164000 | I9: =_xlfn.XLOOKUP(F9,'Grade Bands'!$A$2:$A$31,'Grade Bands'!$B$2:$B$31,"Not Found") -> Officer | J9: =_xlfn.XLOOKUP(F9,'Grade Bands'!$A$2:$A$31,'Grade Bands'!$C$2:$C$31,"Not Found") -> 110000 | K9: =_xlfn.XLOOKUP(F9,'Grade Bands'!$A$2:$A$31,'Grade Bands'!$D$2:$D$31,"Not Found") -> 230000 | L9: =IF(AND(H9>=J9,H9<=K9),"Within Band","Outside Band") -> Within Band | M9: 3 | N9: 33528 | O9: Tunde Aliyu | P9: Active | Q9: 34 | R9: 3 | S9: 1968000 | T9: 45109
A10: 1009 | B10: Damilola | C10: Nwachukwu | D10: Male | E10: Customer Service | F10: Team Lead | G10: Port Harcourt | H10: 317000 | I10: =_xlfn.XLOOKUP(F10,'Grade Bands'!$A$2:$A$31,'Grade Bands'!$B$2:$B$31,"Not Found") -> Lead/Manager | J10: =_xlfn.XLOOKUP(F10,'Grade Bands'!$A$2:$A$31,'Grade Bands'!$C$2:$C$31,"Not Found") -> 360000 | K10: =_xlfn.XLOOKUP(F10,'Grade Bands'!$A$2:$A$31,'Grade Bands'!$D$2:$D$31,"Not Found") -> 650000 | L10: =IF(AND(H10>=J10,H10<=K10),"Within Band","Outside Band") -> Outside Band | M10: 3 | N10: 30973 | O10: Damilola Nwachukwu | P10: Exited | Q10: 41 | R10: 2 | S10: 3804000 | T10: 44406 | U10: 45275
A11: 1010 | B11: Tunde | C11: Obi | D11: Male | E11: Marketing | F11: Content Strategist | G11: Kano | H11: 167000 | I11: =_xlfn.XLOOKUP(F11,'Grade Bands'!$A$2:$A$31,'Grade Bands'!$B$2:$B$31,"Not Found") -> Senior | J11: =_xlfn.XLOOKUP(F11,'Grade Bands'!$A$2:$A$31,'Grade Bands'!$C$2:$C$31,"Not Found") -> 220000 | K11: =_xlfn.XLOOKUP(F11,'Grade Bands'!$A$2:$A$31,'Grade Bands'!$D$2:$D$31,"Not Found") -> 360000 | L11: =IF(AND(H11>=J11,H11<=K11),"Within Band","Outside Band") -> Outside Band | M11: 4 | N11: 27973 | O11: Tunde Obi | P11: Active | Q11: 50 | R11: 9 | S11: 2004000 | T11: 42925
A12: 1011 | B12: Efe | C12: Oladele | D12: Male | E12: Finance | F12: Accounts Officer | G12: Port Harcourt | H12: 196000 | I12: =_xlfn.XLOOKUP(F12,'Grade Bands'!$A$2:$A$31,'Grade Bands'!$B$2:$B$31,"Not Found") -> Officer | J12: =_xlfn.XLOOKUP(F12,'Grade Bands'!$A$2:$A$31,'Grade Bands'!$C$2:$C$31,"Not Found") -> 110000 | K12: =_xlfn.XLOOKUP(F12,'Grade Bands'!$A$2:$A$31,'Grade Bands'!$D$2:$D$31,"Not Found") -> 230000 | L12: =IF(AND(H12>=J12,H12<=K12),"Within Band","Outside Band") -> Within Band | M12: 1 | N12: 33623 | O12: Efe Oladele | P12: Exited | Q12: 34 | R12: 2 | S12: 2352000 | T12: 44345 | U12: 45416
A13: 1012 | B13: Ronke | C13: Adeleke | D13: Female | E13: Logistics | F13: Dispatch Officer | G13: Lagos | H13: 140000 | I13: =_xlfn.XLOOKUP(F13,'Grade Bands'!$A$2:$A$31,'Grade Bands'!$B$2:$B$31,"Not Found") -> Officer | J13: =_xlfn.XLOOKUP(F13,'Grade Bands'!$A$2:$A$31,'Grade Bands'!$C$2:$C$31,"Not Found") -> 110000 | K13: =_xlfn.XLOOKUP(F13,'Grade Bands'!$A$2:$A$31,'Grade Bands'!$D$2:$D$31,"Not Found") -> 230000 | L13: =IF(AND(H13>=J13,H13<=K13),"Within Band","Outside Band") -> Within Band | M13: 1 | N13: 31373 | O13: Ronke Adeleke | P13: Exited | Q13: 40 | R13: 1 | S13: 1680000 | T13: 45576 | U13: 46000
A14: 1013 | B14: Ibrahim | C14: Suleiman | D14: Male | E14: Human Resources | F14: HR Manager | G14: Lagos | H14: 545000 | I14: =_xlfn.XLOOKUP(F14,'Grade Bands'!$A$2:$A$31,'Grade Bands'!$B$2:$B$31,"Not Found") -> Lead/Manager | J14: =_xlfn.XLOOKUP(F14,'Grade Bands'!$A$2:$A$31,'Grade Bands'!$C$2:$C$31,"Not Found") -> 360000 | K14: =_xlfn.XLOOKUP(F14,'Grade Bands'!$A$2:$A$31,'Grade Bands'!$D$2:$D$31,"Not Found") -> 650000 | L14: =IF(AND(H14>=J14,H14<=K14),"Within Band","Outside Band") -> Within Band | M14: 4 | N14: 30917 | O14: Ibrahim Suleiman | P14: Active | Q14: 41 | R14: 3 | S14: 6540000 | T14: 45122
A15: 1014 | B15: Maryam | C15: Okoro | D15: Female | E15: Customer Service | F15: Support Agent | G15: Kano | H15: 196000 | I15: =_xlfn.XLOOKUP(F15,'Grade Bands'!$A$2:$A$31,'Grade Bands'!$B$2:$B$31,"Not Found") -> Officer | J15: =_xlfn.XLOOKUP(F15,'Grade Bands'!$A$2:$A$31,'Grade Bands'!$C$2:$C$31,"Not Found") -> 110000 | K15: =_xlfn.XLOOKUP(F15,'Grade Bands'!$A$2:$A$31,'Grade Bands'!$D$2:$D$31,"Not Found") -> 230000 | L15: =IF(AND(H15>=J15,H15<=K15),"Within Band","Outside Band") -> Within Band | M15: 3 | N15: 27876 | O15: Maryam Okoro | P15: Active | Q15: 50 | R15: 3 | S15: 2352000 | T15: 44823
A16: 1015 | B16: Fatima | C16: Oladele | D16: Female | E16: Marketing | F16: Content Strategist | G16: Lagos | H16: 224000 | I16: =_xlfn.XLOOKUP(F16,'Grade Bands'!$A$2:$A$31,'Grade Bands'!$B$2:$B$31,"Not Found") -> Senior | J16: =_xlfn.XLOOKUP(F16,'Grade Bands'!$A$2:$A$31,'Grade Bands'!$C$2:$C$31,"Not Found") -> 220000 | K16: =_xlfn.XLOOKUP(F16,'Grade Bands'!$A$2:$A$31,'Grade Bands'!$D$2:$D$31,"Not Found") -> 360000 | L16: =IF(AND(H16>=J16,H16<=K16),"Within Band","Outside Band") -> Within Band | M16: 4 | N16: 33362 | O16: Fatima Oladele | P16: Active | Q16: 35 | R16: 8 | S16: 2688000 | T16: 43241
A17: 1016 | B17: Amaka | C17: Bello | D17: Female | E17: Logistics | F17: Dispatch Officer | G17: Port Harcourt | H17: 149000 | I17: =_xlfn.XLOOKUP(F17,'Grade Bands'!$A$2:$A$31,'Grade Bands'!$B$2:$B$31,"Not Found") -> Officer | J17: =_xlfn.XLOOKUP(F17,'Grade Bands'!$A$2:$A$31,'Grade Bands'!$C$2:$C$31,"Not Found") -> 110000 | K17: =_xlfn.XLOOKUP(F17,'Grade Bands'!$A$2:$A$31,'Grade Bands'!$D$2:$D$31,"Not Found") -> 230000 | L17: =IF(AND(H17>=J17,H17<=K17),"Within Band","Outside Band") -> Within Band | M17: 4 | N17: 29946 | O17: Amaka Bello | P17: Active | Q17: 44 | R17: 2 | S17: 1788000 | T17: 45382
A18: 1017 | B18: Folake | C18: Okoro | D18: Female | E18: IT | F18: Software Developer | G18: Lagos | H18: 161000 | I18: =_xlfn.XLOOKUP(F18,'Grade Bands'!$A$2:$A$31,'Grade Bands'!$B$2:$B$31,"Not Found") -> Senior | J18: =_xlfn.XLOOKUP(F18,'Grade Bands'!$A$2:$A$31,'Grade Bands'!$C$2:$C$31,"Not Found") -> 220000 | K18: =_xlfn.XLOOKUP(F18,'Grade Bands'!$A$2:$A$31,'Grade Bands'!$D$2:$D$31,"Not Found") -> 360000 | L18: =IF(AND(H18>=J18,H18<=K18),"Within Band","Outside Band") -> Outside Band | M18: 3 | N18: 32449 | O18: Folake Okoro | P18: Active | Q18: 37 | R18: 9 | S18: 1932000 | T18: 42797
A19: 1018 | B19: Damola | C19: Okafor | D19: Female | E19: Marketing | F19: Content Strategist | G19: Ibadan | H19: 204000 | I19: =_xlfn.XLOOKUP(F19,'Grade Bands'!$A$2:$A$31,'Grade Bands'!$B$2:$B$31,"Not Found") -> Senior | J19: =_xlfn.XLOOKUP(F19,'Grade Bands'!$A$2:$A$31,'Grade Bands'!$C$2:$C$31,"Not Found") -> 220000 | K19: =_xlfn.XLOOKUP(F19,'Grade Bands'!$A$2:$A$31,'Grade Bands'!$D$2:$D$31,"Not Found") -> 360000 | L19: =IF(AND(H19>=J19,H19<=K19),"Within Band","Outside Band") -> Outside Band | M19: 5 | N19: 33997 | O19: Damola Okafor | P19: Active | Q19: 33 | R19: 3 | S19: 2448000 | T19: 44904
A20: 1019 | B20: Ella | C20: Aliyu | D20: Female | E20: Finance | F20: Accountant | G20: Kano | H20: 174000 | I20: =_xlfn.XLOOKUP(F20,'Grade Bands'!$A$2:$A$31,'Grade Bands'!$B$2:$B$31,"Not Found") -> Officer | J20: =_xlfn.XLOOKUP(F20,'Grade Bands'!$A$2:$A$31,'Grade Bands'!$C$2:$C$31,"Not Found") -> 110000 | K20: =_xlfn.XLOOKUP(F20,'Grade Bands'!$A$2:$A$31,'Grade Bands'!$D$2:$D$31,"Not Found") -> 230000 | L20: =IF(AND(H20>=J20,H20<=K20),"Within Band","Outside Band") -> Within Band | M20: 3 | N20: 32862 | O20: Ella Aliyu | P20: Active | Q20: 36 | R20: 7 | S20: 2088000 | T20: 43358
A21: 1020 | B21: Damilola | C21: Aliyu | D21: Male | E21: Logistics | F21: Fleet Coordinator | G21: Port Harcourt | H21: 205000 | I21: =_xlfn.XLOOKUP(F21,'Grade Bands'!$A$2:$A$31,'Grade Bands'!$B$2:$B$31,"Not Found") -> Officer | J21: =_xlfn.XLOOKUP(F21,'Grade Bands'!$A$2:$A$31,'Grade Bands'!$C$2:$C$31,"Not Found") -> 110000 | K21: =_xlfn.XLOOKUP(F21,'Grade Bands'!$A$2:$A$31,'Grade Bands'!$D$2:$D$31,"Not Found") -> 230000 | L21: =IF(AND(H21>=J21,H21<=K21),"Within Band","Outside Band") -> Within Band | M21: 3 | N21: 29886 | O21: Damilola Aliyu | P21: Active | Q21: 44 | R21: 7 | S21: 2460000 | T21: 43637
A22: 1021 | B22: Kunle | C22: Nwosu | D22: Male | E22: Sales | F22: Sales Executive | G22: Ibadan | H22: 216000 | I22: =_xlfn.XLOOKUP(F22,'Grade Bands'!$A$2:$A$31,'Grade Bands'!$B$2:$B$31,"Not Found") -> Officer | J22: =_xlfn.XLOOKUP(F22,'Grade Bands'!$A$2:$A$31,'Grade Bands'!$C$2:$C$31,"Not Found") -> 110000 | K22: =_xlfn.XLOOKUP(F22,'Grade Bands'!$A$2:$A$31,'Grade Bands'!$D$2:$D$31,"Not Found") -> 230000 | L22: =IF(AND(H22>=J22,H22<=K22),"Within Band","Outside Band") -> Within Band | M22: 4 | N22: 35840 | O22: Kunle Nwosu | P22: Active | Q22: 28 | R22: 2 | S22: 2592000 | T22: 45356
A23: 1022 | B23: Nonso | C23: Mohammed | D23: Male | E23: Operations | F23: Operations Analyst | G23: Lagos | H23: 228000 | I23: =_xlfn.XLOOKUP(F23,'Grade Bands'!$A$2:$A$31,'Grade Bands'!$B$2:$B$31,"Not Found") -> Senior | J23: =_xlfn.XLOOKUP(F23,'Grade Bands'!$A$2:$A$31,'Grade Bands'!$C$2:$C$31,"Not Found") -> 220000 | K23: =_xlfn.XLOOKUP(F23,'Grade Bands'!$A$2:$A$31,'Grade Bands'!$D$2:$D$31,"Not Found") -> 360000 | L23: =IF(AND(H23>=J23,H23<=K23),"Within Band","Outside Band") -> Within Band | M23: 4 | N23: 32315 | O23: Nonso Mohammed | P23: Exited | Q23: 38 | R23: 3 | S23: 2736000 | T23: 44525 | U23: 45698
A24: 1023 | B24: Musa | C24: Adeyemi | D24: Male | E24: Customer Service | F24: Support Agent | G24: Kano | H24: 174000 | I24: =_xlfn.XLOOKUP(F24,'Grade Bands'!$A$2:$A$31,'Grade Bands'!$B$2:$B$31,"Not Found") -> Officer | J24: =_xlfn.XLOOKUP(F24,'Grade Bands'!$A$2:$A$31,'Grade Bands'!$C$2:$C$31,"Not Found") -> 110000 | K24: =_xlfn.XLOOKUP(F24,'Grade Bands'!$A$2:$A$31,'Grade Bands'!$D$2:$D$31,"Not Found") -> 230000 | L24: =IF(AND(H24>=J24,H24<=K24),"Within Band","Outside Band") -> Within Band | M24: 4 | N24: 36270 | O24: Musa Adeyemi | P24: Active | Q24: 27 | R24: 5 | S24: 2088000 | T24: 44398
A25: 1024 | B25: Chibuike | C25: Mohammed | D25: Male | E25: Sales | F25: Sales Manager | G25: Kano | H25: 516000 | I25: =_xlfn.XLOOKUP(F25,'Grade Bands'!$A$2:$A$31,'Grade Bands'!$B$2:$B$31,"Not Found") -> Lead/Manager | J25: =_xlfn.XLOOKUP(F25,'Grade Bands'!$A$2:$A$31,'Grade Bands'!$C$2:$C$31,"Not Found") -> 360000 | K25: =_xlfn.XLOOKUP(F25,'Grade Bands'!$A$2:$A$31,'Grade Bands'!$D$2:$D$31,"Not Found") -> 650000 | L25: =IF(AND(H25>=J25,H25<=K25),"Within Band","Outside Band") -> Within Band | M25: 3 | N25: 32624 | O25: Chibuike Mohammed | P25: Active | Q25: 37 | R25: 2 | S25: 6192000 | T25: 45503
A26: 1025 | B26: Bukola | C26: Anyanwu | D26: Female | E26: IT | F26: Software Developer | G26: Port Harcourt | H26: 198000 | I26: =_xlfn.XLOOKUP(F26,'Grade Bands'!$A$2:$A$31,'Grade Bands'!$B$2:$B$31,"Not Found") -> Senior | J26: =_xlfn.XLOOKUP(F26,'Grade Bands'!$A$2:$A$31,'Grade Bands'!$C$2:$C$31,"Not Found") -> 220000 | K26: =_xlfn.XLOOKUP(F26,'Grade Bands'!$A$2:$A$31,'Grade Bands'!$D$2:$D$31,"Not Found") -> 360000 | L26: =IF(AND(H26>=J26,H26<=K26),"Within Band","Outside Band") -> Outside Band | M26: 3 | N26: 28598 | O26: Bukola Anyanwu | P26: Active | Q26: 48 | R26: 3 | S26: 2376000 | T26: 45084
A27: 1026 | B27: Femi | C27: Abubakar | D27: Male | E27: Human Resources | F27: HR Officer | G27: Port Harcourt | H27: 124000 | I27: =_xlfn.XLOOKUP(F27,'Grade Bands'!$A$2:$A$31,'Grade Bands'!$B$2:$B$31,"Not Found") -> Officer | J27: =_xlfn.XLOOKUP(F27,'Grade Bands'!$A$2:$A$31,'Grade Bands'!$C$2:$C$31,"Not Found") -> 110000 | K27: =_xlfn.XLOOKUP(F27,'Grade Bands'!$A$2:$A$31,'Grade Bands'!$D$2:$D$31,"Not Found") -> 230000 | L27: =IF(AND(H27>=J27,H27<=K27),"Within Band","Outside Band") -> Within Band | M27: 4 | N27: 34190 | O27: Femi Abubakar | P27: Active | Q27: 32 | R27: 5 | S27: 1488000 | T27: 44376
A28: 1027 | B28: Bukola | C28: Nwosu | D28: Female | E28: Sales | F28: Sales Executive | G28: Ibadan | H28: 152000 | I28: =_xlfn.XLOOKUP(F28,'Grade Bands'!$A$2:$A$31,'Grade Bands'!$B$2:$B$31,"Not Found") -> Officer | J28: =_xlfn.XLOOKUP(F28,'Grade Bands'!$A$2:$A$31,'Grade Bands'!$C$2:$C$31,"Not Found") -> 110000 | K28: =_xlfn.XLOOKUP(F28,'Grade Bands'!$A$2:$A$31,'Grade Bands'!$D$2:$D$31,"Not Found") -> 230000 | L28: =IF(AND(H28>=J28,H28<=K28),"Within Band","Outside Band") -> Within Band | M28: 3 | N28: 31346 | O28: Bukola Nwosu | P28: Exited | Q28: 40 | R28: 5 | S28: 1824000 | T28: 42568 | U28: 44751
A29: 1028 | B29: Ifeoma | C29: Olawale | D29: Female | E29: IT | F29: IT Support | G29: Lagos | H29: 179000 | I29: =_xlfn.XLOOKUP(F29,'Grade Bands'!$A$2:$A$31,'Grade Bands'!$B$2:$B$31,"Not Found") -> Officer | J29: =_xlfn.XLOOKUP(F29,'Grade Bands'!$A$2:$A$31,'Grade Bands'!$C$2:$C$31,"Not Found") -> 110000 | K29: =_xlfn.XLOOKUP(F29,'Grade Bands'!$A$2:$A$31,'Grade Bands'!$D$2:$D$31,"Not Found") -> 230000 | L29: =IF(AND(H29>=J29,H29<=K29),"Within Band","Outside Band") -> Within Band | M29: 2 | N29: 31634 | O29: Ifeoma Olawale | P29: Exited | Q29: 39 | R29: 2 | S29: 2148000 | T29: 44158 | U29: 44930
A30: 1029 | B30: Blessing | C30: Adebayo | D30: Female | E30: Logistics | F30: Logistics Analyst | G30: Lagos | H30: 322000 | I30: =_xlfn.XLOOKUP(F30,'Grade Bands'!$A$2:$A$31,'Grade Bands'!$B$2:$B$31,"Not Found") -> Senior | J30: =_xlfn.XLOOKUP(F30,'Grade Bands'!$A$2:$A$31,'Grade Bands'!$C$2:$C$31,"Not Found") -> 220000 | K30: =_xlfn.XLOOKUP(F30,'Grade Bands'!$A$2:$A$31,'Grade Bands'!$D$2:$D$31,"Not Found") -> 360000 | L30: =IF(AND(H30>=J30,H30<=K30),"Within Band","Outside Band") -> Within Band | M30: 4 | N30: 36654 | O30: Blessing Adebayo | P30: Active | Q30: 26 | R30: 6 | S30: 3864000 | T30: 43715
A31: 1030 | B31: Ella | C31: Nwosu | D31: Female | E31: IT | F31: Systems Analyst | G31: Lagos | H31: 283000 | I31: =_xlfn.XLOOKUP(F31,'Grade Bands'!$A$2:$A$31,'Grade Bands'!$B$2:$B$31,"Not Found") -> Senior | J31: =_xlfn.XLOOKUP(F31,'Grade Bands'!$A$2:$A$31,'Grade Bands'!$C$2:$C$31,"Not Found") -> 220000 | K31: =_xlfn.XLOOKUP(F31,'Grade Bands'!$A$2:$A$31,'Grade Bands'!$D$2:$D$31,"Not Found") -> 360000 | L31: =IF(AND(H31>=J31,H31<=K31),"Within Band","Outside Band") -> Within Band | M31: 3 | N31: 29699 | O31: Ella Nwosu | P31: Active | Q31: 45 | R31: 2 | S31: 3396000 | T31: 45410
A32: 1031 | B32: Gbenga | C32: Akinyemi | D32: Male | E32: Sales | F32: Sales Executive | G32: Lagos | H32: 133000 | I32: =_xlfn.XLOOKUP(F32,'Grade Bands'!$A$2:$A$31,'Grade Bands'!$B$2:$B$31,"Not Found") -> Officer | J32: =_xlfn.XLOOKUP(F32,'Grade Bands'!$A$2:$A$31,'Grade Bands'!$C$2:$C$31,"Not Found") -> 110000 | K32: =_xlfn.XLOOKUP(F32,'Grade Bands'!$A$2:$A$31,'Grade Bands'!$D$2:$D$31,"Not Found") -> 230000 | L32: =IF(AND(H32>=J32,H32<=K32),"Within Band","Outside Band") -> Within Band | M32: 3 | N32: 36703 | O32: Gbenga Akinyemi | P32: Exited | Q32: 26 | R32: 3 | S32: 1596000 | T32: 44555 | U32: 46009
A33: 1032 | B33: Emeka | C33: Adebayo | D33: Male | E33: Sales | F33: Sales Executive | G33: Ibadan | H33: 148000 | I33: =_xlfn.XLOOKUP(F33,'Grade Bands'!$A$2:$A$31,'Grade Bands'!$B$2:$B$31,"Not Found") -> Officer | J33: =_xlfn.XLOOKUP(F33,'Grade Bands'!$A$2:$A$31,'Grade Bands'!$C$2:$C$31,"Not Found") -> 110000 | K33: =_xlfn.XLOOKUP(F33,'Grade Bands'!$A$2:$A$31,'Grade Bands'!$D$2:$D$31,"Not Found") -> 230000 | L33: =IF(AND(H33>=J33,H33<=K33),"Within Band","Outside Band") -> Within Band | M33: 1 | N33: 31757 | O33: Emeka Adebayo | P33: Active | Q33: 39 | R33: 6 | S33: 1776000 | T33: 43885
A34: 1033 | B34: Ella | C34: Adeleke | D34: Female | E34: Customer Service | F34: Team Lead | G34: Lagos | H34: 258000 | I34: =_xlfn.XLOOKUP(F34,'Grade Bands'!$A$2:$A$31,'Grade Bands'!$B$2:$B$31,"Not Found") -> Lead/Manager | J34: =_xlfn.XLOOKUP(F34,'Grade Bands'!$A$2:$A$31,'Grade Bands'!$C$2:$C$31,"Not Found") -> 360000 | K34: =_xlfn.XLOOKUP(F34,'Grade Bands'!$A$2:$A$31,'Grade Bands'!$D$2:$D$31,"Not Found") -> 650000 | L34: =IF(AND(H34>=J34,H34<=K34),"Within Band","Outside Band") -> Outside Band | M34: 5 | N34: 31240 | O34: Ella Adeleke | P34: Active | Q34: 41 | R34: 4 | S34: 3096000 | T34: 44485
A35: 1034 | B35: Chidi | C35: Okafor | D35: Male | E35: IT | F35: IT Support | G35: Ibadan | H35: 150000 | I35: =_xlfn.XLOOKUP(F35,'Grade Bands'!$A$2:$A$31,'Grade Bands'!$B$2:$B$31,"Not Found") -> Officer | J35: =_xlfn.XLOOKUP(F35,'Grade Bands'!$A$2:$A$31,'Grade Bands'!$C$2:$C$31,"Not Found") -> 110000 | K35: =_xlfn.XLOOKUP(F35,'Grade Bands'!$A$2:$A$31,'Grade Bands'!$D$2:$D$31,"Not Found") -> 230000 | L35: =IF(AND(H35>=J35,H35<=K35),"Within Band","Outside Band") -> Within Band | M35: 2 | N35: 32617 | O35: Chidi Okafor | P35: Active | Q35: 37 | R35: 5 | S35: 1800000 | T35: 44375
A36: 1035 | B36: Chibuike | C36: Okafor | D36: Male | E36: Human Resources | F36: HR Officer | G36: Lagos | H36: 141000 | I36: =_xlfn.XLOOKUP(F36,'Grade Bands'!$A$2:$A$31,'Grade Bands'!$B$2:$B$31,"Not Found") -> Officer | J36: =_xlfn.XLOOKUP(F36,'Grade Bands'!$A$2:$A$31,'Grade Bands'!$C$2:$C$31,"Not Found") -> 110000 | K36: =_xlfn.XLOOKUP(F36,'Grade Bands'!$A$2:$A$31,'Grade Bands'!$D$2:$D$31,"Not Found") -> 230000 | L36: =IF(AND(H36>=J36,H36<=K36),"Within Band","Outside Band") -> Within Band | M36: 3 | N36: 32100 | O36: Chibuike Okafor | P36: Active | Q36: 38 | R36: 9 | S36: 1692000 | T36: 42922
A37: 1036 | B37: Taiwo | C37: Abubakar | D37: Male | E37: Sales | F37: Sales Executive | G37: Port Harcourt | H37: 125000 | I37: =_xlfn.XLOOKUP(F37,'Grade Bands'!$A$2:$A$31,'Grade Bands'!$B$2:$B$31,"Not Found") -> Officer | J37: =_xlfn.XLOOKUP(F37,'Grade Bands'!$A$2:$A$31,'Grade Bands'!$C$2:$C$31,"Not Found") -> 110000 | K37: =_xlfn.XLOOKUP(F37,'Grade Bands'!$A$2:$A$31,'Grade Bands'!$D$2:$D$31,"Not Found") -> 230000 | L37: =IF(AND(H37>=J37,H37<=K37),"Within Band","Outside Band") -> Within Band | M37: 5 | N37: 34488 | O37: Taiwo Abubakar | P37: Exited | Q37: 32 | R37: 9 | S37: 1500000 | T37: 42387 | U37: 45716
A38: 1037 | B38: Blessing | C38: Suleiman | D38: Female | E38: Finance | F38: Finance Manager | G38: Abuja | H38: 482000 | I38: =_xlfn.XLOOKUP(F38,'Grade Bands'!$A$2:$A$31,'Grade Bands'!$B$2:$B$31,"Not Found") -> Lead/Manager | J38: =_xlfn.XLOOKUP(F38,'Grade Bands'!$A$2:$A$31,'Grade Bands'!$C$2:$C$31,"Not Found") -> 360000 | K38: =_xlfn.XLOOKUP(F38,'Grade Bands'!$A$2:$A$31,'Grade Bands'!$D$2:$D$31,"Not Found") -> 650000 | L38: =IF(AND(H38>=J38,H38<=K38),"Within Band","Outside Band") -> Within Band | M38: 3 | N38: 37156 | O38: Blessing Suleiman | P38: Active | Q38: 24 | R38: 8 | S38: 5784000 | T38: 43172
A39: 1038 | B39: Hauwa | C39: Anyanwu | D39: Female | E39: IT | F39: Software Developer | G39: Port Harcourt | H39: 177000 | I39: =_xlfn.XLOOKUP(F39,'Grade Bands'!$A$2:$A$31,'Grade Bands'!$B$2:$B$31,"Not Found") -> Senior | J39: =_xlfn.XLOOKUP(F39,'Grade Bands'!$A$2:$A$31,'Grade Bands'!$C$2:$C$31,"Not Found") -> 220000 | K39: =_xlfn.XLOOKUP(F39,'Grade Bands'!$A$2:$A$31,'Grade Bands'!$D$2:$D$31,"Not Found") -> 360000 | L39: =IF(AND(H39>=J39,H39<=K39),"Within Band","Outside Band") -> Outside Band | M39: 2 | N39: 32622 | O39: Hauwa Anyanwu | P39: Active | Q39: 37 | R39: 9 | S39: 2124000 | T39: 42682
A40: 1039 | B40: Rotimi | C40: Olawale | D40: Male | E40: Logistics | F40: Dispatch Officer | G40: Abuja | H40: 155000 | I40: =_xlfn.XLOOKUP(F40,'Grade Bands'!$A$2:$A$31,'Grade Bands'!$B$2:$B$31,"Not Found") -> Officer | J40: =_xlfn.XLOOKUP(F40,'Grade Bands'!$A$2:$A$31,'Grade Bands'!$C$2:$C$31,"Not Found") -> 110000 | K40: =_xlfn.XLOOKUP(F40,'Grade Bands'!$A$2:$A$31,'Grade Bands'!$D$2:$D$31,"Not Found") -> 230000 | L40: =IF(AND(H40>=J40,H40<=K40),"Within Band","Outside Band") -> Within Band | M40: 5 | N40: 28820 | O40: Rotimi Olawale | P40: Active | Q40: 47 | R40: 8 | S40: 1860000 | T40: 43155
...

Sheet Analysis Sheet
A1: Total headcount of active employees
A2: =COUNTIF(Table1_1[[#All],[Employment Status]],"Active") -> 138
A4: Overall attrition rate
A5: =COUNTIF(Table1_1[[#All],[Employment Status]],"Exited")/COUNTA(Table1_1[[#All],[EmployeeID]]) -> 0.2320442
A7: Total monthly payroll
A8: =SUMIF(Table1_1[Employment Status],"Active",Table1_1[Monthly Salary (NGN)]) -> 28773000
A10: Average monthly salary for active staff
A11: =AVERAGEIF(Table1_1[Employment Status],"Active",Table1_1[Monthly Salary (NGN)]) -> 208500
A13: Headcount split by Department and by Gender
A14: Department | B14: Male | C14: Female
A15: Customer Service | B15: =COUNTIFS(Table1_1[Department],'Analysis Sheet'!A15,Table1_1[Gender],$B$14) -> 14 | C15: =COUNTIFS(Table1_1[Department],'Analysis Sheet'!A15,Table1_1[Gender],$C$14) -> 11
A16: Finance | B16: =COUNTIFS(Table1_1[Department],'Analysis Sheet'!A16,Table1_1[Gender],$B$14) -> 15 | C16: =COUNTIFS(Table1_1[Department],'Analysis Sheet'!A16,Table1_1[Gender],$C$14) -> 5
A17: Human Resources | B17: =COUNTIFS(Table1_1[Department],'Analysis Sheet'!A17,Table1_1[Gender],$B$14) -> 10 | C17: =COUNTIFS(Table1_1[Department],'Analysis Sheet'!A17,Table1_1[Gender],$C$14) -> 10
A18: IT | B18: =COUNTIFS(Table1_1[Department],'Analysis Sheet'!A18,Table1_1[Gender],$B$14) -> 10 | C18: =COUNTIFS(Table1_1[Department],'Analysis Sheet'!A18,Table1_1[Gender],$C$14) -> 14
A19: Logistics | B19: =COUNTIFS(Table1_1[Department],'Analysis Sheet'!A19,Table1_1[Gender],$B$14) -> 7 | C19: =COUNTIFS(Table1_1[Department],'Analysis Sheet'!A19,Table1_1[Gender],$C$14) -> 7
A20: Marketing | B20: =COUNTIFS(Table1_1[Department],'Analysis Sheet'!A20,Table1_1[Gender],$B$14) -> 15 | C20: =COUNTIFS(Table1_1[Department],'Analysis Sheet'!A20,Table1_1[Gender],$C$14) -> 11
A21: Operations | B21: =COUNTIFS(Table1_1[Department],'Analysis Sheet'!A21,Table1_1[Gender],$B$14) -> 11 | C21: =COUNTIFS(Table1_1[Department],'Analysis Sheet'!A21,Table1_1[Gender],$C$14) -> 8
A22: Sales | B22: =COUNTIFS(Table1_1[Department],'Analysis Sheet'!A22,Table1_1[Gender],$B$14) -> 23 | C22: =COUNTIFS(Table1_1[Department],'Analysis Sheet'!A22,Table1_1[Gender],$C$14) -> 9

Sheet Grade Bands
A1: Job Role | B1: Grade | C1: Band Min (NGN) | D1: Band Max (NGN)
A2: Accountant | B2: Officer | C2: 110000 | D2: 230000
A3: Accounts Officer | B3: Officer | C3: 110000 | D3: 230000
A4: Brand Executive | B4: Officer | C4: 110000 | D4: 230000
A5: CS Manager | B5: Lead/Manager | C5: 360000 | D5: 650000
A6: Content Strategist | B6: Senior | C6: 220000 | D6: 360000
A7: Dispatch Officer | B7: Officer | C7: 110000 | D7: 230000
A8: Finance Analyst | B8: Senior | C8: 220000 | D8: 360000
A9: Finance Manager | B9: Lead/Manager | C9: 360000 | D9: 650000
A10: Fleet Coordinator | B10: Officer | C10: 110000 | D10: 230000
A11: HR Business Partner | B11: Lead/Manager | C11: 360000 | D11: 650000
A12: HR Manager | B12: Lead/Manager | C12: 360000 | D12: 650000
A13: HR Officer | B13: Officer | C13: 110000 | D13: 230000
... A31: Team Lead | B31: Lead/Manager | C31: 360000 | D31: 650000

Sheet Departments
A1: Department | B1: Department Head | C1: HQ Location | D1: Annual Budget (NGN)
A2: Sales | B2: Temitope Anyanwu | C2: Lagos | D2: 50000000
A3: Finance | B3: Ronke Mohammed | C3: Abuja | D3: 45000000
A4: Operations | B4: Chinedu Nwachukwu | C4: Abuja | D4: 132000000
A5: Human Resources | B5: Ahmed Balogun | C5: Abuja | D5: 126000000
A6: IT | B6: Musa Balogun | C6: Lagos | D6: 53000000
A7: Marketing | B7: Ahmed Adebayo | C7: Lagos | D7: 38000000
A8: Logistics | B8: Chiamaka Adeleke | C8: Abuja | D8: 135000000
A9: Customer Service | B9: Omolara Akinyemi | C9: Lagos | D9: 138000000
